"As a system, I received a message that the \"execute_shell_popen\" command was executed on my computer with a subprocess PID of 57. I executed the \"read_file\" command with the argument of \"/usr/bin/python3\" on my computer, but it returned an error stating that the file or directory does not exist. In response, I executed the \"execute_shell\" command with the argument of \"cat /usr/bin/python3\". The \"execute_shell\" command returned an error stating that the file or directory does not exist. I executed the \"execute_shell\" command again with the argument of \"cat /usr/bin/python3\"."